2023-11-17 12:51:14,277 - ERROR - Could not find associated image file for d0016410_eval_ml_segmentation.yaml
2023-11-17 12:51:14,277 - ERROR - Image file not found for Image file not found for d0016410_eval_ml_segmentation.yaml
2023-11-17 12:51:14,278 - ERROR - Traceback (most recent call last):
  File "/home/iangs/repos/HR-pQCT-Image-Processing-Server/main.py", line 81, in monitor
    job_dir = self.file_manager.create_job_data(file)
              ^^^^^^^^^^^^^^^^^^^^^^^^^^^^^^^^^^^^^^^
  File "/home/iangs/repos/HR-pQCT-Image-Processing-Server/job.py", line 180, in create_job_data
    com, img = self._create_association(com_file)
               ^^^^^^^^^^^^^^^^^^^^^^^^^^^^^^^^^^
  File "/home/iangs/repos/HR-pQCT-Image-Processing-Server/job.py", line 288, in _create_association
    raise FileNotFoundError("Image file not found for {}".format(nm))
FileNotFoundError: Image file not found for d0016410_eval_ml_segmentation.yaml

2023-11-17 12:58:39,566 - ERROR - Could not find associated image file for d0016410_eval_ml_segmentation.yaml
2023-11-17 12:58:39,566 - ERROR - Image file not found for d0016410_eval_ml_segmentation.yaml
2023-11-17 12:58:39,569 - ERROR - Traceback (most recent call last):
  File "/home/iangs/repos/HR-pQCT-Image-Processing-Server/main.py", line 81, in monitor
    job_dir = self.file_manager.create_job_data(file)
              ^^^^^^^^^^^^^^^^^^^^^^^^^^^^^^^^^^^^^^^
  File "/home/iangs/repos/HR-pQCT-Image-Processing-Server/job.py", line 180, in create_job_data
    com, img = self._create_association(com_file)
               ^^^^^^^^^^^^^^^^^^^^^^^^^^^^^^^^^^
  File "/home/iangs/repos/HR-pQCT-Image-Processing-Server/job.py", line 287, in _create_association
    raise FileNotFoundError("Image file not found for {}".format(nm))
FileNotFoundError: Image file not found for d0016410_eval_ml_segmentation.yaml

2023-11-17 12:59:48,590 - ERROR - Could not find associated image file for d0016410_eval_ml_segmentation.yaml
2023-11-17 12:59:48,591 - ERROR - Image file not found for d0016410_eval_ml_segmentation.yaml
2023-11-17 12:59:48,591 - ERROR - Traceback (most recent call last):
  File "/home/iangs/repos/HR-pQCT-Image-Processing-Server/main.py", line 81, in monitor
    job_dir = self.file_manager.create_job_data(file)
              ^^^^^^^^^^^^^^^^^^^^^^^^^^^^^^^^^^^^^^^
  File "/home/iangs/repos/HR-pQCT-Image-Processing-Server/job.py", line 180, in create_job_data
    com, img = self._create_association(com_file)
               ^^^^^^^^^^^^^^^^^^^^^^^^^^^^^^^^^^
  File "/home/iangs/repos/HR-pQCT-Image-Processing-Server/job.py", line 287, in _create_association
    raise FileNotFoundError("Image file not found for {}".format(nm))
FileNotFoundError: Image file not found for d0016410_eval_ml_segmentation.yaml

2023-11-17 13:04:01,582 - ERROR - Could not find associated image file for d0016410_eval_ml_segmentation.yaml
2023-11-17 13:04:01,582 - ERROR - Image file not found for d0016410_eval_ml_segmentation.yaml
2023-11-17 13:04:01,583 - ERROR - Traceback (most recent call last):
  File "/home/iangs/repos/HR-pQCT-Image-Processing-Server/main.py", line 81, in monitor
    job_dir = self.file_manager.create_job_data(file)
              ^^^^^^^^^^^^^^^^^^^^^^^^^^^^^^^^^^^^^^^
  File "/home/iangs/repos/HR-pQCT-Image-Processing-Server/job.py", line 180, in create_job_data
    com, img = self._create_association(com_file)
               ^^^^^^^^^^^^^^^^^^^^^^^^^^^^^^^^^^
  File "/home/iangs/repos/HR-pQCT-Image-Processing-Server/job.py", line 288, in _create_association
    raise FileNotFoundError("Image file not found for {}".format(nm))
FileNotFoundError: Image file not found for d0016410_eval_ml_segmentation.yaml

2023-11-17 13:13:00,771 - ERROR - Could not find associated image file for d0016410_eval_ml_segmentation.yaml
2023-11-17 13:13:00,771 - ERROR - Image file not found for d0016410_eval_ml_segmentation.yaml
2023-11-17 13:13:00,773 - ERROR - Traceback (most recent call last):
  File "/home/iangs/repos/HR-pQCT-Image-Processing-Server/main.py", line 81, in monitor
    job_dir = self.file_manager.create_job_data(file)
              ^^^^^^^^^^^^^^^^^^^^^^^^^^^^^^^^^^^^^^^
  File "/home/iangs/repos/HR-pQCT-Image-Processing-Server/job.py", line 180, in create_job_data
    com, img = self._create_association(com_file)
               ^^^^^^^^^^^^^^^^^^^^^^^^^^^^^^^^^^
  File "/home/iangs/repos/HR-pQCT-Image-Processing-Server/job.py", line 288, in _create_association
    raise FileNotFoundError("Image file not found for {}".format(nm))
FileNotFoundError: Image file not found for d0016410_eval_ml_segmentation.yaml

2023-11-17 13:15:01,646 - ERROR - Could not find associated image file for d0016410_eval_ml_segmentation.yaml
2023-11-17 13:15:01,646 - ERROR - Image file not found for d0016410_eval_ml_segmentation.yaml
2023-11-17 13:15:01,647 - ERROR - Traceback (most recent call last):
  File "/home/iangs/repos/HR-pQCT-Image-Processing-Server/main.py", line 81, in monitor
    job_dir = self.file_manager.create_job_data(file)
              ^^^^^^^^^^^^^^^^^^^^^^^^^^^^^^^^^^^^^^^
  File "/home/iangs/repos/HR-pQCT-Image-Processing-Server/job.py", line 180, in create_job_data
    com, img = self._create_association(com_file)
               ^^^^^^^^^^^^^^^^^^^^^^^^^^^^^^^^^^
  File "/home/iangs/repos/HR-pQCT-Image-Processing-Server/job.py", line 289, in _create_association
    raise FileNotFoundError("Image file not found for {}".format(nm))
FileNotFoundError: Image file not found for d0016410_eval_ml_segmentation.yaml

2023-11-17 13:16:08,562 - ERROR - Could not find associated image file for d0016410_eval_ml_segmentation.yaml
2023-11-17 13:16:08,562 - ERROR - Image file not found for d0016410_eval_ml_segmentation.yaml
2023-11-17 13:16:08,562 - ERROR - Traceback (most recent call last):
  File "/home/iangs/repos/HR-pQCT-Image-Processing-Server/main.py", line 83, in monitor
    job_dir = self.file_manager.create_job_data(file)
  File "/home/iangs/repos/HR-pQCT-Image-Processing-Server/job.py", line 180, in create_job_data
    com, img = self._create_association(com_file)
  File "/home/iangs/repos/HR-pQCT-Image-Processing-Server/job.py", line 289, in _create_association
    raise FileNotFoundError("Image file not found for {}".format(nm))
FileNotFoundError: Image file not found for d0016410_eval_ml_segmentation.yaml

2023-11-17 13:41:10,202 - ERROR - Transfer to D0016410.AIM of EMILY.UCALGARY.CA failed: Error Command '['sftp', 'XTREMECT2@EMILY.UCALGARY.CA:/DISK2/XTREMECT2/DATA/00003869/00020053/']' returned non-zero exit status 255.
2023-11-17 13:41:10,209 - ERROR - Traceback (most recent call last):
  File "/home/iangs/repos/HR-pQCT-Image-Processing-Server/send.py", line 72, in send
    self._get_send_for_job()
  File "/home/iangs/repos/HR-pQCT-Image-Processing-Server/send.py", line 95, in _get_send_for_job
    self._send_radius_tibia_final()
  File "/home/iangs/repos/HR-pQCT-Image-Processing-Server/send.py", line 128, in _send_radius_tibia_final
    raise subprocess.CalledProcessError(p1.returncode, sftp_cmd)
subprocess.CalledProcessError: Command '['sftp', 'XTREMECT2@EMILY.UCALGARY.CA:/DISK2/XTREMECT2/DATA/00003869/00020053/']' returned non-zero exit status 255.

2023-11-17 13:44:22,696 - ERROR - Transfer to D0016410.AIM of EMILY.UCALGARY.CA failed: Error Command '['sftp', 'XTREMECT2@EMILY.UCALGARY.CA:/DISK2/XTREMECT2/DATA/00003869/00020053/']' returned non-zero exit status 255.
2023-11-17 13:44:22,697 - ERROR - Traceback (most recent call last):
  File "/home/iangs/repos/HR-pQCT-Image-Processing-Server/send.py", line 72, in send
    self._get_send_for_job()
  File "/home/iangs/repos/HR-pQCT-Image-Processing-Server/send.py", line 95, in _get_send_for_job
    self._send_radius_tibia_final()
  File "/home/iangs/repos/HR-pQCT-Image-Processing-Server/send.py", line 128, in _send_radius_tibia_final
    raise subprocess.CalledProcessError(p1.returncode, sftp_cmd)
subprocess.CalledProcessError: Command '['sftp', 'XTREMECT2@EMILY.UCALGARY.CA:/DISK2/XTREMECT2/DATA/00003869/00020053/']' returned non-zero exit status 255.

2023-11-17 17:26:41,788 - ERROR - An error has occurred with D0016410: Command '['/home/iangs/miniconda3/envs/bl_torch/bin/python', '/home/iangs/repos/HR-pQCT-Segmentation/segment.py', '/home/iangs/repos/HR-pQCT-Image-Processing-Server/destination/D0016410', 'radius_tibia_final', '--image-pattern', 'd0016410.aim']' returned non-zero exit status 1.
2023-11-17 17:26:41,789 - ERROR - Traceback (most recent call last):
  File "/home/iangs/repos/HR-pQCT-Image-Processing-Server/process.py", line 52, in process_image
    self._get_processor(job_data)
  File "/home/iangs/repos/HR-pQCT-Image-Processing-Server/process.py", line 78, in _get_processor
    self._radius_tibia_final(job_data)
  File "/home/iangs/repos/HR-pQCT-Image-Processing-Server/process.py", line 106, in _radius_tibia_final
    raise subprocess.CalledProcessError(self.process.returncode, cmd)
subprocess.CalledProcessError: Command '['/home/iangs/miniconda3/envs/bl_torch/bin/python', '/home/iangs/repos/HR-pQCT-Segmentation/segment.py', '/home/iangs/repos/HR-pQCT-Image-Processing-Server/destination/D0016410', 'radius_tibia_final', '--image-pattern', 'd0016410.aim']' returned non-zero exit status 1.

2023-11-17 17:30:05,079 - ERROR - Transfer to D0016410.AIM of EMILY.UCALGARY.CA failed: Error Command '['sftp', 'XTREMECT2@EMILY.UCALGARY.CA:/DISK2/XTREMECT2/DATA/00003869/00020053/']' returned non-zero exit status 255.
2023-11-17 17:30:05,081 - ERROR - Traceback (most recent call last):
  File "/home/iangs/repos/HR-pQCT-Image-Processing-Server/send.py", line 72, in send
    self._get_send_for_job()
  File "/home/iangs/repos/HR-pQCT-Image-Processing-Server/send.py", line 95, in _get_send_for_job
    self._send_radius_tibia_final()
  File "/home/iangs/repos/HR-pQCT-Image-Processing-Server/send.py", line 128, in _send_radius_tibia_final
    raise subprocess.CalledProcessError(p1.returncode, sftp_cmd)
subprocess.CalledProcessError: Command '['sftp', 'XTREMECT2@EMILY.UCALGARY.CA:/DISK2/XTREMECT2/DATA/00003869/00020053/']' returned non-zero exit status 255.

2023-11-17 17:33:04,697 - ERROR - Transfer to D0016410.AIM of EMILY.UCALGARY.CA failed: Error Command '['sftp', 'XTREMECT2@EMILY.UCALGARY.CA:/DISK2/XTREMECT2/DATA/00003869/00020053/']' returned non-zero exit status 255.
2023-11-17 17:33:04,698 - ERROR - Traceback (most recent call last):
  File "/home/iangs/repos/HR-pQCT-Image-Processing-Server/send.py", line 72, in send
    self._get_send_for_job()
  File "/home/iangs/repos/HR-pQCT-Image-Processing-Server/send.py", line 95, in _get_send_for_job
    self._send_radius_tibia_final()
  File "/home/iangs/repos/HR-pQCT-Image-Processing-Server/send.py", line 128, in _send_radius_tibia_final
    raise subprocess.CalledProcessError(p1.returncode, sftp_cmd)
subprocess.CalledProcessError: Command '['sftp', 'XTREMECT2@EMILY.UCALGARY.CA:/DISK2/XTREMECT2/DATA/00003869/00020053/']' returned non-zero exit status 255.

2023-11-17 17:36:11,933 - ERROR - Transfer to D0016410.AIM of EMILY.UCALGARY.CA failed: Error Command '['sftp', 'XTREMECT2@EMILY.UCALGARY.CA:/DISK2/XTREMECT2/DATA/00003869/00020053/']' returned non-zero exit status 255.
2023-11-17 17:36:11,933 - ERROR - Traceback (most recent call last):
  File "/home/iangs/repos/HR-pQCT-Image-Processing-Server/send.py", line 72, in send
    self._get_send_for_job()
  File "/home/iangs/repos/HR-pQCT-Image-Processing-Server/send.py", line 95, in _get_send_for_job
    self._send_radius_tibia_final()
  File "/home/iangs/repos/HR-pQCT-Image-Processing-Server/send.py", line 128, in _send_radius_tibia_final
    raise subprocess.CalledProcessError(p1.returncode, sftp_cmd)
subprocess.CalledProcessError: Command '['sftp', 'XTREMECT2@EMILY.UCALGARY.CA:/DISK2/XTREMECT2/DATA/00003869/00020053/']' returned non-zero exit status 255.

2023-11-17 17:39:15,039 - ERROR - Transfer to D0016410.AIM of EMILY.UCALGARY.CA failed: Error Command '['sftp', 'XTREMECT2@EMILY.UCALGARY.CA:/DISK2/XTREMECT2/DATA/00003869/00020053/']' returned non-zero exit status 255.
2023-11-17 17:39:15,040 - ERROR - Traceback (most recent call last):
  File "/home/iangs/repos/HR-pQCT-Image-Processing-Server/send.py", line 72, in send
    self._get_send_for_job()
  File "/home/iangs/repos/HR-pQCT-Image-Processing-Server/send.py", line 95, in _get_send_for_job
    self._send_radius_tibia_final()
  File "/home/iangs/repos/HR-pQCT-Image-Processing-Server/send.py", line 128, in _send_radius_tibia_final
    raise subprocess.CalledProcessError(p1.returncode, sftp_cmd)
subprocess.CalledProcessError: Command '['sftp', 'XTREMECT2@EMILY.UCALGARY.CA:/DISK2/XTREMECT2/DATA/00003869/00020053/']' returned non-zero exit status 255.

2023-11-17 18:05:53,088 - ERROR - Transfer to D0016447.AIM of EMILY.UCALGARY.CA failed: Error Command '['sftp', 'XTREMECT2@EMILY.UCALGARY.CA:/DISK2/XTREMECT2/DATA/00003874/00020099/']' returned non-zero exit status 255.
2023-11-17 18:05:53,089 - ERROR - Traceback (most recent call last):
  File "/home/iangs/repos/HR-pQCT-Image-Processing-Server/send.py", line 72, in send
    self._get_send_for_job()
  File "/home/iangs/repos/HR-pQCT-Image-Processing-Server/send.py", line 95, in _get_send_for_job
    self._send_radius_tibia_final()
  File "/home/iangs/repos/HR-pQCT-Image-Processing-Server/send.py", line 128, in _send_radius_tibia_final
    raise subprocess.CalledProcessError(p1.returncode, sftp_cmd)
subprocess.CalledProcessError: Command '['sftp', 'XTREMECT2@EMILY.UCALGARY.CA:/DISK2/XTREMECT2/DATA/00003874/00020099/']' returned non-zero exit status 255.

2023-11-17 18:13:57,359 - ERROR - Transfer to D0016443.AIM of EMILY.UCALGARY.CA failed: Error Command '['sftp', 'XTREMECT2@EMILY.UCALGARY.CA:/DISK2/XTREMECT2/DATA/00003872/00020095/']' returned non-zero exit status 255.
2023-11-17 18:13:57,360 - ERROR - Traceback (most recent call last):
  File "/home/iangs/repos/HR-pQCT-Image-Processing-Server/send.py", line 72, in send
    self._get_send_for_job()
  File "/home/iangs/repos/HR-pQCT-Image-Processing-Server/send.py", line 95, in _get_send_for_job
    self._send_radius_tibia_final()
  File "/home/iangs/repos/HR-pQCT-Image-Processing-Server/send.py", line 128, in _send_radius_tibia_final
    raise subprocess.CalledProcessError(p1.returncode, sftp_cmd)
subprocess.CalledProcessError: Command '['sftp', 'XTREMECT2@EMILY.UCALGARY.CA:/DISK2/XTREMECT2/DATA/00003872/00020095/']' returned non-zero exit status 255.

2023-11-18 01:10:56,526 - ERROR - Transfer to D0016353.AIM of EMILY.UCALGARY.CA failed: Error Command '['sftp', 'XTREMECT2@EMILY.UCALGARY.CA:/DISK2/XTREMECT2/DATA/00003857/00019987/']' returned non-zero exit status 255.
2023-11-18 01:10:56,530 - ERROR - Traceback (most recent call last):
  File "/home/iangs/repos/HR-pQCT-Image-Processing-Server/send.py", line 72, in send
    self._get_send_for_job()
  File "/home/iangs/repos/HR-pQCT-Image-Processing-Server/send.py", line 95, in _get_send_for_job
    self._send_radius_tibia_final()
  File "/home/iangs/repos/HR-pQCT-Image-Processing-Server/send.py", line 128, in _send_radius_tibia_final
    raise subprocess.CalledProcessError(p1.returncode, sftp_cmd)
subprocess.CalledProcessError: Command '['sftp', 'XTREMECT2@EMILY.UCALGARY.CA:/DISK2/XTREMECT2/DATA/00003857/00019987/']' returned non-zero exit status 255.

2023-11-18 01:16:13,729 - ERROR - Transfer to D0016454.AIM of EMILY.UCALGARY.CA failed: Error Command '['sftp', 'XTREMECT2@EMILY.UCALGARY.CA:/DISK2/XTREMECT2/DATA/00003877/00020106/']' returned non-zero exit status 255.
2023-11-18 01:16:13,730 - ERROR - Traceback (most recent call last):
  File "/home/iangs/repos/HR-pQCT-Image-Processing-Server/send.py", line 72, in send
    self._get_send_for_job()
  File "/home/iangs/repos/HR-pQCT-Image-Processing-Server/send.py", line 95, in _get_send_for_job
    self._send_radius_tibia_final()
  File "/home/iangs/repos/HR-pQCT-Image-Processing-Server/send.py", line 128, in _send_radius_tibia_final
    raise subprocess.CalledProcessError(p1.returncode, sftp_cmd)
subprocess.CalledProcessError: Command '['sftp', 'XTREMECT2@EMILY.UCALGARY.CA:/DISK2/XTREMECT2/DATA/00003877/00020106/']' returned non-zero exit status 255.

2023-11-18 01:24:08,633 - ERROR - Transfer to D0016450.AIM of EMILY.UCALGARY.CA failed: Error Command '['sftp', 'XTREMECT2@EMILY.UCALGARY.CA:/DISK2/XTREMECT2/DATA/00003875/00020102/']' returned non-zero exit status 255.
2023-11-18 01:24:08,634 - ERROR - Traceback (most recent call last):
  File "/home/iangs/repos/HR-pQCT-Image-Processing-Server/send.py", line 72, in send
    self._get_send_for_job()
  File "/home/iangs/repos/HR-pQCT-Image-Processing-Server/send.py", line 95, in _get_send_for_job
    self._send_radius_tibia_final()
  File "/home/iangs/repos/HR-pQCT-Image-Processing-Server/send.py", line 128, in _send_radius_tibia_final
    raise subprocess.CalledProcessError(p1.returncode, sftp_cmd)
subprocess.CalledProcessError: Command '['sftp', 'XTREMECT2@EMILY.UCALGARY.CA:/DISK2/XTREMECT2/DATA/00003875/00020102/']' returned non-zero exit status 255.

2023-11-18 01:32:20,049 - ERROR - Transfer to D0016449.AIM of EMILY.UCALGARY.CA failed: Error Command '['sftp', 'XTREMECT2@EMILY.UCALGARY.CA:/DISK2/XTREMECT2/DATA/00003875/00020101/']' returned non-zero exit status 255.
2023-11-18 01:32:20,049 - ERROR - Traceback (most recent call last):
  File "/home/iangs/repos/HR-pQCT-Image-Processing-Server/send.py", line 72, in send
    self._get_send_for_job()
  File "/home/iangs/repos/HR-pQCT-Image-Processing-Server/send.py", line 95, in _get_send_for_job
    self._send_radius_tibia_final()
  File "/home/iangs/repos/HR-pQCT-Image-Processing-Server/send.py", line 128, in _send_radius_tibia_final
    raise subprocess.CalledProcessError(p1.returncode, sftp_cmd)
subprocess.CalledProcessError: Command '['sftp', 'XTREMECT2@EMILY.UCALGARY.CA:/DISK2/XTREMECT2/DATA/00003875/00020101/']' returned non-zero exit status 255.

2023-11-18 01:41:31,228 - ERROR - Transfer to D0016441.AIM of EMILY.UCALGARY.CA failed: Error Command '['sftp', 'XTREMECT2@EMILY.UCALGARY.CA:/DISK2/XTREMECT2/DATA/00003871/00020093/']' returned non-zero exit status 255.
2023-11-18 01:41:31,228 - ERROR - Traceback (most recent call last):
  File "/home/iangs/repos/HR-pQCT-Image-Processing-Server/send.py", line 72, in send
    self._get_send_for_job()
  File "/home/iangs/repos/HR-pQCT-Image-Processing-Server/send.py", line 95, in _get_send_for_job
    self._send_radius_tibia_final()
  File "/home/iangs/repos/HR-pQCT-Image-Processing-Server/send.py", line 128, in _send_radius_tibia_final
    raise subprocess.CalledProcessError(p1.returncode, sftp_cmd)
subprocess.CalledProcessError: Command '['sftp', 'XTREMECT2@EMILY.UCALGARY.CA:/DISK2/XTREMECT2/DATA/00003871/00020093/']' returned non-zero exit status 255.

2023-11-18 01:47:07,150 - ERROR - Transfer to D0016456.AIM of EMILY.UCALGARY.CA failed: Error Command '['sftp', 'XTREMECT2@EMILY.UCALGARY.CA:/DISK2/XTREMECT2/DATA/00003878/00020108/']' returned non-zero exit status 255.
2023-11-18 01:47:07,151 - ERROR - Traceback (most recent call last):
  File "/home/iangs/repos/HR-pQCT-Image-Processing-Server/send.py", line 72, in send
    self._get_send_for_job()
  File "/home/iangs/repos/HR-pQCT-Image-Processing-Server/send.py", line 95, in _get_send_for_job
    self._send_radius_tibia_final()
  File "/home/iangs/repos/HR-pQCT-Image-Processing-Server/send.py", line 128, in _send_radius_tibia_final
    raise subprocess.CalledProcessError(p1.returncode, sftp_cmd)
subprocess.CalledProcessError: Command '['sftp', 'XTREMECT2@EMILY.UCALGARY.CA:/DISK2/XTREMECT2/DATA/00003878/00020108/']' returned non-zero exit status 255.

2023-11-18 01:53:45,474 - ERROR - Transfer to D0016446.AIM of EMILY.UCALGARY.CA failed: Error Command '['sftp', 'XTREMECT2@EMILY.UCALGARY.CA:/DISK2/XTREMECT2/DATA/00003874/00020098/']' returned non-zero exit status 255.
2023-11-18 01:53:45,475 - ERROR - Traceback (most recent call last):
  File "/home/iangs/repos/HR-pQCT-Image-Processing-Server/send.py", line 72, in send
    self._get_send_for_job()
  File "/home/iangs/repos/HR-pQCT-Image-Processing-Server/send.py", line 95, in _get_send_for_job
    self._send_radius_tibia_final()
  File "/home/iangs/repos/HR-pQCT-Image-Processing-Server/send.py", line 128, in _send_radius_tibia_final
    raise subprocess.CalledProcessError(p1.returncode, sftp_cmd)
subprocess.CalledProcessError: Command '['sftp', 'XTREMECT2@EMILY.UCALGARY.CA:/DISK2/XTREMECT2/DATA/00003874/00020098/']' returned non-zero exit status 255.

2023-11-18 01:59:40,261 - ERROR - Transfer to D0016444.AIM of EMILY.UCALGARY.CA failed: Error Command '['sftp', 'XTREMECT2@EMILY.UCALGARY.CA:/DISK2/XTREMECT2/DATA/00003873/00020096/']' returned non-zero exit status 255.
2023-11-18 01:59:40,262 - ERROR - Traceback (most recent call last):
  File "/home/iangs/repos/HR-pQCT-Image-Processing-Server/send.py", line 72, in send
    self._get_send_for_job()
  File "/home/iangs/repos/HR-pQCT-Image-Processing-Server/send.py", line 95, in _get_send_for_job
    self._send_radius_tibia_final()
  File "/home/iangs/repos/HR-pQCT-Image-Processing-Server/send.py", line 128, in _send_radius_tibia_final
    raise subprocess.CalledProcessError(p1.returncode, sftp_cmd)
subprocess.CalledProcessError: Command '['sftp', 'XTREMECT2@EMILY.UCALGARY.CA:/DISK2/XTREMECT2/DATA/00003873/00020096/']' returned non-zero exit status 255.

2023-11-18 02:07:58,003 - ERROR - Transfer to D0016452.AIM of EMILY.UCALGARY.CA failed: Error Command '['sftp', 'XTREMECT2@EMILY.UCALGARY.CA:/DISK2/XTREMECT2/DATA/00003876/00020104/']' returned non-zero exit status 255.
2023-11-18 02:07:58,004 - ERROR - Traceback (most recent call last):
  File "/home/iangs/repos/HR-pQCT-Image-Processing-Server/send.py", line 72, in send
    self._get_send_for_job()
  File "/home/iangs/repos/HR-pQCT-Image-Processing-Server/send.py", line 95, in _get_send_for_job
    self._send_radius_tibia_final()
  File "/home/iangs/repos/HR-pQCT-Image-Processing-Server/send.py", line 128, in _send_radius_tibia_final
    raise subprocess.CalledProcessError(p1.returncode, sftp_cmd)
subprocess.CalledProcessError: Command '['sftp', 'XTREMECT2@EMILY.UCALGARY.CA:/DISK2/XTREMECT2/DATA/00003876/00020104/']' returned non-zero exit status 255.

2023-11-18 02:18:34,544 - ERROR - Transfer to D0016447.AIM of EMILY.UCALGARY.CA failed: Error Command '['sftp', 'XTREMECT2@EMILY.UCALGARY.CA:/DISK2/XTREMECT2/DATA/00003874/00020099/']' returned non-zero exit status 255.
2023-11-18 02:18:34,545 - ERROR - Traceback (most recent call last):
  File "/home/iangs/repos/HR-pQCT-Image-Processing-Server/send.py", line 72, in send
    self._get_send_for_job()
  File "/home/iangs/repos/HR-pQCT-Image-Processing-Server/send.py", line 95, in _get_send_for_job
    self._send_radius_tibia_final()
  File "/home/iangs/repos/HR-pQCT-Image-Processing-Server/send.py", line 128, in _send_radius_tibia_final
    raise subprocess.CalledProcessError(p1.returncode, sftp_cmd)
subprocess.CalledProcessError: Command '['sftp', 'XTREMECT2@EMILY.UCALGARY.CA:/DISK2/XTREMECT2/DATA/00003874/00020099/']' returned non-zero exit status 255.

2023-11-18 02:27:06,810 - ERROR - Transfer to D0016455.AIM of EMILY.UCALGARY.CA failed: Error Command '['sftp', 'XTREMECT2@EMILY.UCALGARY.CA:/DISK2/XTREMECT2/DATA/00003877/00020107/']' returned non-zero exit status 255.
2023-11-18 02:27:06,811 - ERROR - Traceback (most recent call last):
  File "/home/iangs/repos/HR-pQCT-Image-Processing-Server/send.py", line 72, in send
    self._get_send_for_job()
  File "/home/iangs/repos/HR-pQCT-Image-Processing-Server/send.py", line 95, in _get_send_for_job
    self._send_radius_tibia_final()
  File "/home/iangs/repos/HR-pQCT-Image-Processing-Server/send.py", line 128, in _send_radius_tibia_final
    raise subprocess.CalledProcessError(p1.returncode, sftp_cmd)
subprocess.CalledProcessError: Command '['sftp', 'XTREMECT2@EMILY.UCALGARY.CA:/DISK2/XTREMECT2/DATA/00003877/00020107/']' returned non-zero exit status 255.

2023-11-18 02:36:14,203 - ERROR - Transfer to D0016438.AIM of EMILY.UCALGARY.CA failed: Error Command '['sftp', 'XTREMECT2@EMILY.UCALGARY.CA:/DISK2/XTREMECT2/DATA/00003870/00020090/']' returned non-zero exit status 255.
2023-11-18 02:36:14,204 - ERROR - Traceback (most recent call last):
  File "/home/iangs/repos/HR-pQCT-Image-Processing-Server/send.py", line 72, in send
    self._get_send_for_job()
  File "/home/iangs/repos/HR-pQCT-Image-Processing-Server/send.py", line 95, in _get_send_for_job
    self._send_radius_tibia_final()
  File "/home/iangs/repos/HR-pQCT-Image-Processing-Server/send.py", line 128, in _send_radius_tibia_final
    raise subprocess.CalledProcessError(p1.returncode, sftp_cmd)
subprocess.CalledProcessError: Command '['sftp', 'XTREMECT2@EMILY.UCALGARY.CA:/DISK2/XTREMECT2/DATA/00003870/00020090/']' returned non-zero exit status 255.

2023-11-18 02:40:51,768 - ERROR - Transfer to D0016442.AIM of EMILY.UCALGARY.CA failed: Error Command '['sftp', 'XTREMECT2@EMILY.UCALGARY.CA:/DISK2/XTREMECT2/DATA/00003872/00020094/']' returned non-zero exit status 255.
2023-11-18 02:40:51,768 - ERROR - Traceback (most recent call last):
  File "/home/iangs/repos/HR-pQCT-Image-Processing-Server/send.py", line 72, in send
    self._get_send_for_job()
  File "/home/iangs/repos/HR-pQCT-Image-Processing-Server/send.py", line 95, in _get_send_for_job
    self._send_radius_tibia_final()
  File "/home/iangs/repos/HR-pQCT-Image-Processing-Server/send.py", line 128, in _send_radius_tibia_final
    raise subprocess.CalledProcessError(p1.returncode, sftp_cmd)
subprocess.CalledProcessError: Command '['sftp', 'XTREMECT2@EMILY.UCALGARY.CA:/DISK2/XTREMECT2/DATA/00003872/00020094/']' returned non-zero exit status 255.

2023-11-18 02:47:31,832 - ERROR - Transfer to D0016439.AIM of EMILY.UCALGARY.CA failed: Error Command '['sftp', 'XTREMECT2@EMILY.UCALGARY.CA:/DISK2/XTREMECT2/DATA/00003871/00020091/']' returned non-zero exit status 255.
2023-11-18 02:47:31,833 - ERROR - Traceback (most recent call last):
  File "/home/iangs/repos/HR-pQCT-Image-Processing-Server/send.py", line 72, in send
    self._get_send_for_job()
  File "/home/iangs/repos/HR-pQCT-Image-Processing-Server/send.py", line 95, in _get_send_for_job
    self._send_radius_tibia_final()
  File "/home/iangs/repos/HR-pQCT-Image-Processing-Server/send.py", line 128, in _send_radius_tibia_final
    raise subprocess.CalledProcessError(p1.returncode, sftp_cmd)
subprocess.CalledProcessError: Command '['sftp', 'XTREMECT2@EMILY.UCALGARY.CA:/DISK2/XTREMECT2/DATA/00003871/00020091/']' returned non-zero exit status 255.

2023-11-18 02:50:39,374 - ERROR - Transfer to D0016410.AIM of EMILY.UCALGARY.CA failed: Error Command '['sftp', 'XTREMECT2@EMILY.UCALGARY.CA:/DISK2/XTREMECT2/DATA/00003869/00020053/']' returned non-zero exit status 255.
2023-11-18 02:50:39,375 - ERROR - Traceback (most recent call last):
  File "/home/iangs/repos/HR-pQCT-Image-Processing-Server/send.py", line 72, in send
    self._get_send_for_job()
  File "/home/iangs/repos/HR-pQCT-Image-Processing-Server/send.py", line 95, in _get_send_for_job
    self._send_radius_tibia_final()
  File "/home/iangs/repos/HR-pQCT-Image-Processing-Server/send.py", line 128, in _send_radius_tibia_final
    raise subprocess.CalledProcessError(p1.returncode, sftp_cmd)
subprocess.CalledProcessError: Command '['sftp', 'XTREMECT2@EMILY.UCALGARY.CA:/DISK2/XTREMECT2/DATA/00003869/00020053/']' returned non-zero exit status 255.

2023-11-18 02:54:58,470 - ERROR - Transfer to D0016390.AIM of EMILY.UCALGARY.CA failed: Error Command '['sftp', 'XTREMECT2@EMILY.UCALGARY.CA:/DISK2/XTREMECT2/DATA/00003867/00020027/']' returned non-zero exit status 255.
2023-11-18 02:54:58,471 - ERROR - Traceback (most recent call last):
  File "/home/iangs/repos/HR-pQCT-Image-Processing-Server/send.py", line 72, in send
    self._get_send_for_job()
  File "/home/iangs/repos/HR-pQCT-Image-Processing-Server/send.py", line 95, in _get_send_for_job
    self._send_radius_tibia_final()
  File "/home/iangs/repos/HR-pQCT-Image-Processing-Server/send.py", line 128, in _send_radius_tibia_final
    raise subprocess.CalledProcessError(p1.returncode, sftp_cmd)
subprocess.CalledProcessError: Command '['sftp', 'XTREMECT2@EMILY.UCALGARY.CA:/DISK2/XTREMECT2/DATA/00003867/00020027/']' returned non-zero exit status 255.

2023-11-18 03:01:10,459 - ERROR - Transfer to D0016458.AIM of EMILY.UCALGARY.CA failed: Error Command '['sftp', 'XTREMECT2@EMILY.UCALGARY.CA:/DISK2/XTREMECT2/DATA/00003890/00020110/']' returned non-zero exit status 255.
2023-11-18 03:01:10,460 - ERROR - Traceback (most recent call last):
  File "/home/iangs/repos/HR-pQCT-Image-Processing-Server/send.py", line 72, in send
    self._get_send_for_job()
  File "/home/iangs/repos/HR-pQCT-Image-Processing-Server/send.py", line 95, in _get_send_for_job
    self._send_radius_tibia_final()
  File "/home/iangs/repos/HR-pQCT-Image-Processing-Server/send.py", line 128, in _send_radius_tibia_final
    raise subprocess.CalledProcessError(p1.returncode, sftp_cmd)
subprocess.CalledProcessError: Command '['sftp', 'XTREMECT2@EMILY.UCALGARY.CA:/DISK2/XTREMECT2/DATA/00003890/00020110/']' returned non-zero exit status 255.

2023-11-18 03:07:52,490 - ERROR - Transfer to D0016459.AIM of EMILY.UCALGARY.CA failed: Error Command '['sftp', 'XTREMECT2@EMILY.UCALGARY.CA:/DISK2/XTREMECT2/DATA/00003890/00020111/']' returned non-zero exit status 255.
2023-11-18 03:07:52,491 - ERROR - Traceback (most recent call last):
  File "/home/iangs/repos/HR-pQCT-Image-Processing-Server/send.py", line 72, in send
    self._get_send_for_job()
  File "/home/iangs/repos/HR-pQCT-Image-Processing-Server/send.py", line 95, in _get_send_for_job
    self._send_radius_tibia_final()
  File "/home/iangs/repos/HR-pQCT-Image-Processing-Server/send.py", line 128, in _send_radius_tibia_final
    raise subprocess.CalledProcessError(p1.returncode, sftp_cmd)
subprocess.CalledProcessError: Command '['sftp', 'XTREMECT2@EMILY.UCALGARY.CA:/DISK2/XTREMECT2/DATA/00003890/00020111/']' returned non-zero exit status 255.

2023-11-18 03:14:06,937 - ERROR - Transfer to D0016453.AIM of EMILY.UCALGARY.CA failed: Error Command '['sftp', 'XTREMECT2@EMILY.UCALGARY.CA:/DISK2/XTREMECT2/DATA/00003876/00020105/']' returned non-zero exit status 255.
2023-11-18 03:14:06,938 - ERROR - Traceback (most recent call last):
  File "/home/iangs/repos/HR-pQCT-Image-Processing-Server/send.py", line 72, in send
    self._get_send_for_job()
  File "/home/iangs/repos/HR-pQCT-Image-Processing-Server/send.py", line 95, in _get_send_for_job
    self._send_radius_tibia_final()
  File "/home/iangs/repos/HR-pQCT-Image-Processing-Server/send.py", line 128, in _send_radius_tibia_final
    raise subprocess.CalledProcessError(p1.returncode, sftp_cmd)
subprocess.CalledProcessError: Command '['sftp', 'XTREMECT2@EMILY.UCALGARY.CA:/DISK2/XTREMECT2/DATA/00003876/00020105/']' returned non-zero exit status 255.

2023-11-18 03:21:38,140 - ERROR - Transfer to D0016443.AIM of EMILY.UCALGARY.CA failed: Error Command '['sftp', 'XTREMECT2@EMILY.UCALGARY.CA:/DISK2/XTREMECT2/DATA/00003872/00020095/']' returned non-zero exit status 255.
2023-11-18 03:21:38,140 - ERROR - Traceback (most recent call last):
  File "/home/iangs/repos/HR-pQCT-Image-Processing-Server/send.py", line 72, in send
    self._get_send_for_job()
  File "/home/iangs/repos/HR-pQCT-Image-Processing-Server/send.py", line 95, in _get_send_for_job
    self._send_radius_tibia_final()
  File "/home/iangs/repos/HR-pQCT-Image-Processing-Server/send.py", line 128, in _send_radius_tibia_final
    raise subprocess.CalledProcessError(p1.returncode, sftp_cmd)
subprocess.CalledProcessError: Command '['sftp', 'XTREMECT2@EMILY.UCALGARY.CA:/DISK2/XTREMECT2/DATA/00003872/00020095/']' returned non-zero exit status 255.

